<?xml version="1.0" ?>
<!-- Generated using onshape-to-robot -->
<!-- Onshape https://cad.onshape.com/documents/ea63b3bac09efd13a5a2ece1/w/b645e56964cd291cbb9b3be9/e/c8f0478ecdab5caa319eb8ad -->
<robot name="urdf">
  <!-- Link urdf_base -->
  <link name="urdf_base">
    <inertial>
      <origin xyz="-8.29496e-06 -0.000300406 -0.0300781" rpy="0 0 0"/>
      <mass value="0.160151"/>
      <inertia ixx="0.000152936" ixy="-1.316e-09" ixz="-3.023e-08" iyy="0.000143814" iyz="-1.15712e-06" izz="0.000162111"/>
    </inertial>
    <!-- Part ee_main_body__cnc_machine -->
    <visual>
      <origin xyz="0 0 -0.061025" rpy="-0 0 1.5708"/>
      <geometry>
        <mesh filename="package://assets/ee_main_body__cnc_machine.stl"/>
      </geometry>
      <material name="ee_main_body__cnc_machine_material">
        <color rgba="0.866667 0.321569 0.156863 1"/>
      </material>
    </visual>
    <collision>
      <origin xyz="0 0 -0.061025" rpy="-0 0 1.5708"/>
      <geometry>
        <mesh filename="package://assets/ee_main_body__cnc_machine.stl"/>
      </geometry>
    </collision>
    <!-- Part link_0 -->
    <visual>
      <origin xyz="0 0 -0.01385" rpy="0 0 2.35619"/>
      <geometry>
        <mesh filename="package://assets/link_0.stl"/>
      </geometry>
      <material name="link_0_material">
        <color rgba="0.866667 0.321569 0.156863 1"/>
      </material>
    </visual>
    <collision>
      <origin xyz="0 0 -0.01385" rpy="0 0 2.35619"/>
      <geometry>
        <mesh filename="package://assets/link_0.stl"/>
      </geometry>
    </collision>
    <!-- Part servo_horn -->
    <visual>
      <origin xyz="0.0180312 0.0180312 0.01295" rpy="-1.5708 0 0.785398"/>
      <geometry>
        <mesh filename="package://assets/servo_horn.stl"/>
      </geometry>
      <material name="servo_horn_material">
        <color rgba="0.960784 0.960784 0.964706 1"/>
      </material>
    </visual>
    <collision>
      <origin xyz="0.0180312 0.0180312 0.01295" rpy="-1.5708 0 0.785398"/>
      <geometry>
        <mesh filename="package://assets/servo_horn.stl"/>
      </geometry>
    </collision>
    <!-- Part 93655a224_no_threads_male_female_threaded_hex_standoff -->
    <visual>
      <origin xyz="-0.023 -0.013 -0.05785" rpy="-0 -0 -1.5708"/>
      <geometry>
        <mesh filename="package://assets/93655a224_no_threads_male_female_threaded_hex_standoff.stl"/>
      </geometry>
      <material name="93655a224_no_threads_male_female_threaded_hex_standoff_material">
        <color rgba="0.866667 0.321569 0.156863 1"/>
      </material>
    </visual>
    <collision>
      <origin xyz="-0.023 -0.013 -0.05785" rpy="-0 -0 -1.5708"/>
      <geometry>
        <mesh filename="package://assets/93655a224_no_threads_male_female_threaded_hex_standoff.stl"/>
      </geometry>
    </collision>
    <!-- Part pin_support_plate__waterjetted -->
    <visual>
      <origin xyz="0 0 -0.017675" rpy="-3.14159 -0 -1.5708"/>
      <geometry>
        <mesh filename="package://assets/pin_support_plate__waterjetted.stl"/>
      </geometry>
      <material name="pin_support_plate__waterjetted_material">
        <color rgba="0.866667 0.321569 0.156863 1"/>
      </material>
    </visual>
    <collision>
      <origin xyz="0 0 -0.017675" rpy="-3.14159 -0 -1.5708"/>
      <geometry>
        <mesh filename="package://assets/pin_support_plate__waterjetted.stl"/>
      </geometry>
    </collision>
    <!-- Part 93657a001_nylon_unthreaded_spacer -->
    <visual>
      <origin xyz="-0.023 0.013 -0.02185" rpy="-3.14159 -0 -1.5708"/>
      <geometry>
        <mesh filename="package://assets/93657a001_nylon_unthreaded_spacer.stl"/>
      </geometry>
      <material name="93657a001_nylon_unthreaded_spacer_material">
        <color rgba="0.866667 0.321569 0.156863 1"/>
      </material>
    </visual>
    <collision>
      <origin xyz="-0.023 0.013 -0.02185" rpy="-3.14159 -0 -1.5708"/>
      <geometry>
        <mesh filename="package://assets/93657a001_nylon_unthreaded_spacer.stl"/>
      </geometry>
    </collision>
    <!-- Part 93657a001_nylon_unthreaded_spacer_2 -->
    <visual>
      <origin xyz="-0.023 -0.013 -0.02185" rpy="-3.14159 -0 -1.5708"/>
      <geometry>
        <mesh filename="package://assets/93657a001_nylon_unthreaded_spacer.stl"/>
      </geometry>
      <material name="93657a001_nylon_unthreaded_spacer_2_material">
        <color rgba="0.866667 0.321569 0.156863 1"/>
      </material>
    </visual>
    <collision>
      <origin xyz="-0.023 -0.013 -0.02185" rpy="-3.14159 -0 -1.5708"/>
      <geometry>
        <mesh filename="package://assets/93657a001_nylon_unthreaded_spacer.stl"/>
      </geometry>
    </collision>
    <!-- Part 93657a001_nylon_unthreaded_spacer_3 -->
    <visual>
      <origin xyz="0.023 -0.013 -0.02185" rpy="-3.14159 -0 -1.5708"/>
      <geometry>
        <mesh filename="package://assets/93657a001_nylon_unthreaded_spacer.stl"/>
      </geometry>
      <material name="93657a001_nylon_unthreaded_spacer_3_material">
        <color rgba="0.866667 0.321569 0.156863 1"/>
      </material>
    </visual>
    <collision>
      <origin xyz="0.023 -0.013 -0.02185" rpy="-3.14159 -0 -1.5708"/>
      <geometry>
        <mesh filename="package://assets/93657a001_nylon_unthreaded_spacer.stl"/>
      </geometry>
    </collision>
    <!-- Part 93657a001_nylon_unthreaded_spacer_4 -->
    <visual>
      <origin xyz="0.023 0.013 -0.02185" rpy="-3.14159 -0 -1.5708"/>
      <geometry>
        <mesh filename="package://assets/93657a001_nylon_unthreaded_spacer.stl"/>
      </geometry>
      <material name="93657a001_nylon_unthreaded_spacer_4_material">
        <color rgba="0.866667 0.321569 0.156863 1"/>
      </material>
    </visual>
    <collision>
      <origin xyz="0.023 0.013 -0.02185" rpy="-3.14159 -0 -1.5708"/>
      <geometry>
        <mesh filename="package://assets/93657a001_nylon_unthreaded_spacer.stl"/>
      </geometry>
    </collision>
    <!-- Part 93655a224_no_threads_male_female_threaded_hex_standoff_2 -->
    <visual>
      <origin xyz="-0.023 0.013 -0.05785" rpy="-0 -0 -1.5708"/>
      <geometry>
        <mesh filename="package://assets/93655a224_no_threads_male_female_threaded_hex_standoff.stl"/>
      </geometry>
      <material name="93655a224_no_threads_male_female_threaded_hex_standoff_2_material">
        <color rgba="0.866667 0.321569 0.156863 1"/>
      </material>
    </visual>
    <collision>
      <origin xyz="-0.023 0.013 -0.05785" rpy="-0 -0 -1.5708"/>
      <geometry>
        <mesh filename="package://assets/93655a224_no_threads_male_female_threaded_hex_standoff.stl"/>
      </geometry>
    </collision>
    <!-- Part 93655a224_no_threads_male_female_threaded_hex_standoff_3 -->
    <visual>
      <origin xyz="0.023 0.013 -0.05785" rpy="-0 -0 -1.5708"/>
      <geometry>
        <mesh filename="package://assets/93655a224_no_threads_male_female_threaded_hex_standoff.stl"/>
      </geometry>
      <material name="93655a224_no_threads_male_female_threaded_hex_standoff_3_material">
        <color rgba="0.866667 0.321569 0.156863 1"/>
      </material>
    </visual>
    <collision>
      <origin xyz="0.023 0.013 -0.05785" rpy="-0 -0 -1.5708"/>
      <geometry>
        <mesh filename="package://assets/93655a224_no_threads_male_female_threaded_hex_standoff.stl"/>
      </geometry>
    </collision>
    <!-- Part 93655a224_no_threads_male_female_threaded_hex_standoff_4 -->
    <visual>
      <origin xyz="0.023 -0.013 -0.05785" rpy="-0 -0 -1.5708"/>
      <geometry>
        <mesh filename="package://assets/93655a224_no_threads_male_female_threaded_hex_standoff.stl"/>
      </geometry>
      <material name="93655a224_no_threads_male_female_threaded_hex_standoff_4_material">
        <color rgba="0.866667 0.321569 0.156863 1"/>
      </material>
    </visual>
    <collision>
      <origin xyz="0.023 -0.013 -0.05785" rpy="-0 -0 -1.5708"/>
      <geometry>
        <mesh filename="package://assets/93655a224_no_threads_male_female_threaded_hex_standoff.stl"/>
      </geometry>
    </collision>
  </link>
  <!-- Link urdf_link1 -->
  <link name="urdf_link1">
    <inertial>
      <origin xyz="-0.00267039 -0.00842889 0.112927" rpy="0 0 0"/>
      <mass value="0.403309"/>
      <inertia ixx="0.00223346" ixy="1.40932e-05" ixz="4.94564e-05" iyy="0.00210963" iyz="-0.000261342" izz="0.000483596"/>
    </inertial>
    <!-- Part link_1_4_bracket -->
    <visual>
      <origin xyz="-0 -0.0487 0.07615" rpy="-1.5708 1.5708 0"/>
      <geometry>
        <mesh filename="package://assets/link_1_4_bracket.stl"/>
      </geometry>
      <material name="link_1_4_bracket_material">
        <color rgba="0.372549 0.654902 0.239216 1"/>
      </material>
    </visual>
    <collision>
      <origin xyz="-0 -0.0487 0.07615" rpy="-1.5708 1.5708 0"/>
      <geometry>
        <mesh filename="package://assets/link_1_4_bracket.stl"/>
      </geometry>
    </collision>
    <!-- Part link_1_3_waterjet -->
    <visual>
      <origin xyz="-0 -0.0487 0.07615" rpy="-1.5708 1.5708 0"/>
      <geometry>
        <mesh filename="package://assets/link_1_3_waterjet.stl"/>
      </geometry>
      <material name="link_1_3_waterjet_material">
        <color rgba="0.372549 0.654902 0.239216 1"/>
      </material>
    </visual>
    <collision>
      <origin xyz="-0 -0.0487 0.07615" rpy="-1.5708 1.5708 0"/>
      <geometry>
        <mesh filename="package://assets/link_1_3_waterjet.stl"/>
      </geometry>
    </collision>
    <!-- Part link_2_2_cnc_mill -->
    <visual>
      <origin xyz="-0 -0.0487 0.07615" rpy="-1.5708 1.5708 0"/>
      <geometry>
        <mesh filename="package://assets/link_2_2_cnc_mill.stl"/>
      </geometry>
      <material name="link_2_2_cnc_mill_material">
        <color rgba="0.372549 0.654902 0.239216 1"/>
      </material>
    </visual>
    <collision>
      <origin xyz="-0 -0.0487 0.07615" rpy="-1.5708 1.5708 0"/>
      <geometry>
        <mesh filename="package://assets/link_2_2_cnc_mill.stl"/>
      </geometry>
    </collision>
    <!-- Part link_1_1_bracket -->
    <visual>
      <origin xyz="-0 -0.0487 0.07615" rpy="-1.5708 1.5708 0"/>
      <geometry>
        <mesh filename="package://assets/link_1_1_bracket.stl"/>
      </geometry>
      <material name="link_1_1_bracket_material">
        <color rgba="0.372549 0.654902 0.239216 1"/>
      </material>
    </visual>
    <collision>
      <origin xyz="-0 -0.0487 0.07615" rpy="-1.5708 1.5708 0"/>
      <geometry>
        <mesh filename="package://assets/link_1_1_bracket.stl"/>
      </geometry>
    </collision>
    <!-- Part casing -->
    <visual>
      <origin xyz="-0.01375 0.00265 0.1589" rpy="3.14159 0 1.5708"/>
      <geometry>
        <mesh filename="package://assets/casing.stl"/>
      </geometry>
      <material name="casing_material">
        <color rgba="0.14902 0.129412 0.129412 1"/>
      </material>
    </visual>
    <collision>
      <origin xyz="-0.01375 0.00265 0.1589" rpy="3.14159 0 1.5708"/>
      <geometry>
        <mesh filename="package://assets/casing.stl"/>
      </geometry>
    </collision>
    <!-- Part wj_fdp0_0005_danpan_20181204_4 -->
    <visual>
      <origin xyz="0.03475 0.02015 0.1589" rpy="0 0 -1.5708"/>
      <geometry>
        <mesh filename="package://assets/wj_fdp0_0005_danpan_20181204_4.stl"/>
      </geometry>
      <material name="wj_fdp0_0005_danpan_20181204_4_material">
        <color rgba="0.647059 0.647059 0.647059 1"/>
      </material>
    </visual>
    <collision>
      <origin xyz="0.03475 0.02015 0.1589" rpy="0 0 -1.5708"/>
      <geometry>
        <mesh filename="package://assets/wj_fdp0_0005_danpan_20181204_4.stl"/>
      </geometry>
    </collision>
    <!-- Part output_disk_free_spining -->
    <visual>
      <origin xyz="-0.04035 0.02015 0.1589" rpy="0 0 -1.5708"/>
      <geometry>
        <mesh filename="package://assets/output_disk_free_spining.stl"/>
      </geometry>
      <material name="output_disk_free_spining_material">
        <color rgba="0.647059 0.647059 0.647059 1"/>
      </material>
    </visual>
    <collision>
      <origin xyz="-0.04035 0.02015 0.1589" rpy="0 0 -1.5708"/>
      <geometry>
        <mesh filename="package://assets/output_disk_free_spining.stl"/>
      </geometry>
    </collision>
    <!-- Part outputgear_41 -->
    <visual>
      <origin xyz="-0.00325 0.02015 0.1589" rpy="1.5708 0 1.5708"/>
      <geometry>
        <mesh filename="package://assets/outputgear_41.stl"/>
      </geometry>
      <material name="outputgear_41_material">
        <color rgba="0.14902 0.129412 0.129412 1"/>
      </material>
    </visual>
    <collision>
      <origin xyz="-0.00325 0.02015 0.1589" rpy="1.5708 0 1.5708"/>
      <geometry>
        <mesh filename="package://assets/outputgear_41.stl"/>
      </geometry>
    </collision>
    <!-- Part casing_2 -->
    <visual>
      <origin xyz="0.03075 0.00265 0.1589" rpy="-3.14159 0 -1.5708"/>
      <geometry>
        <mesh filename="package://assets/casing__2.stl"/>
      </geometry>
      <material name="casing_2_material">
        <color rgba="0.14902 0.129412 0.129412 1"/>
      </material>
    </visual>
    <collision>
      <origin xyz="0.03075 0.00265 0.1589" rpy="-3.14159 0 -1.5708"/>
      <geometry>
        <mesh filename="package://assets/casing__2.stl"/>
      </geometry>
    </collision>
    <!-- Part casing_3 -->
    <visual>
      <origin xyz="-0.03075 0.00265 0.1589" rpy="0 0 -1.5708"/>
      <geometry>
        <mesh filename="package://assets/casing__3.stl"/>
      </geometry>
      <material name="casing_3_material">
        <color rgba="0.14902 0.129412 0.129412 1"/>
      </material>
    </visual>
    <collision>
      <origin xyz="-0.03075 0.00265 0.1589" rpy="0 0 -1.5708"/>
      <geometry>
        <mesh filename="package://assets/casing__3.stl"/>
      </geometry>
    </collision>
    <!-- Part wj_dp00_0011_17 -->
    <visual>
      <origin xyz="0.03555 0.02015 0.1589" rpy="-0 -0 1.5708"/>
      <geometry>
        <mesh filename="package://assets/wj_dp00_0011_17.stl"/>
      </geometry>
      <material name="wj_dp00_0011_17_material">
        <color rgba="0.647059 0.647059 0.647059 1"/>
      </material>
    </visual>
    <collision>
      <origin xyz="0.03555 0.02015 0.1589" rpy="-0 -0 1.5708"/>
      <geometry>
        <mesh filename="package://assets/wj_dp00_0011_17.stl"/>
      </geometry>
    </collision>
    <!-- Part output_shaft -->
    <visual>
      <origin xyz="-0.03505 0.02015 0.1589" rpy="0 0 -1.5708"/>
      <geometry>
        <mesh filename="package://assets/output_shaft.stl"/>
      </geometry>
      <material name="output_shaft_material">
        <color rgba="0.647059 0.647059 0.647059 1"/>
      </material>
    </visual>
    <collision>
      <origin xyz="-0.03505 0.02015 0.1589" rpy="0 0 -1.5708"/>
      <geometry>
        <mesh filename="package://assets/output_shaft.stl"/>
      </geometry>
    </collision>
    <!-- Part cover -->
    <visual>
      <origin xyz="-0 -0.0255 0.0081" rpy="-1.5708 -0 -1.5708"/>
      <geometry>
        <mesh filename="package://assets/cover.stl"/>
      </geometry>
      <material name="cover_material">
        <color rgba="0.341176 0.32549 0.32549 1"/>
      </material>
    </visual>
    <collision>
      <origin xyz="-0 -0.0255 0.0081" rpy="-1.5708 -0 -1.5708"/>
      <geometry>
        <mesh filename="package://assets/cover.stl"/>
      </geometry>
    </collision>
    <!-- Part ge_27 -->
    <visual>
      <origin xyz="0.0180312 -0.0180312 0.0081" rpy="-1.5708 -0 -0.785398"/>
      <geometry>
        <mesh filename="package://assets/ge_27.stl"/>
      </geometry>
      <material name="ge_27_material">
        <color rgba="1 0 0 1"/>
      </material>
    </visual>
    <collision>
      <origin xyz="0.0180312 -0.0180312 0.0081" rpy="-1.5708 -0 -0.785398"/>
      <geometry>
        <mesh filename="package://assets/ge_27.stl"/>
      </geometry>
    </collision>
    <!-- Part cover_2 -->
    <visual>
      <origin xyz="-0 -0.0255 0.0081" rpy="-1.5708 -0 -1.5708"/>
      <geometry>
        <mesh filename="package://assets/cover__2.stl"/>
      </geometry>
      <material name="cover_2_material">
        <color rgba="0.341176 0.32549 0.32549 1"/>
      </material>
    </visual>
    <collision>
      <origin xyz="-0 -0.0255 0.0081" rpy="-1.5708 -0 -1.5708"/>
      <geometry>
        <mesh filename="package://assets/cover__2.stl"/>
      </geometry>
    </collision>
    <!-- Part cover_3 -->
    <visual>
      <origin xyz="-0 -0.0255 0.0081" rpy="-1.5708 -0 -1.5708"/>
      <geometry>
        <mesh filename="package://assets/cover__3.stl"/>
      </geometry>
      <material name="cover_3_material">
        <color rgba="0.341176 0.32549 0.32549 1"/>
      </material>
    </visual>
    <collision>
      <origin xyz="-0 -0.0255 0.0081" rpy="-1.5708 -0 -1.5708"/>
      <geometry>
        <mesh filename="package://assets/cover__3.stl"/>
      </geometry>
    </collision>
    <!-- Part mounting_bracket_bottom -->
    <visual>
      <origin xyz="-0 -0.04235 0.0179" rpy="-1.5708 1.5708 0"/>
      <geometry>
        <mesh filename="package://assets/mounting_bracket_bottom.stl"/>
      </geometry>
      <material name="mounting_bracket_bottom_material">
        <color rgba="0.14902 0.121569 0.121569 1"/>
      </material>
    </visual>
    <collision>
      <origin xyz="-0 -0.04235 0.0179" rpy="-1.5708 1.5708 0"/>
      <geometry>
        <mesh filename="package://assets/mounting_bracket_bottom.stl"/>
      </geometry>
    </collision>
  </link>
  <!-- Link urdf_link2 -->
  <link name="urdf_link2">
    <inertial>
      <origin xyz="0 -0.0647118 0.03635" rpy="0 0 0"/>
      <mass value="0.103498"/>
      <inertia ixx="0.000154243" ixy="0" ixz="-0" iyy="0.000127312" iyz="-0" izz="0.000155274"/>
    </inertial>
    <!-- Part bracket_2 -->
    <visual>
      <origin xyz="0 -0.06435 -0.003" rpy="-0 0 1.5708"/>
      <geometry>
        <mesh filename="package://assets/bracket_2.stl"/>
      </geometry>
      <material name="bracket_2_material">
        <color rgba="0.980392 0.713725 0.00392157 1"/>
      </material>
    </visual>
    <collision>
      <origin xyz="0 -0.06435 -0.003" rpy="-0 0 1.5708"/>
      <geometry>
        <mesh filename="package://assets/bracket_2.stl"/>
      </geometry>
    </collision>
    <!-- Part bracket_2_2 -->
    <visual>
      <origin xyz="0 -0.06435 -0.003" rpy="-0 0 1.5708"/>
      <geometry>
        <mesh filename="package://assets/bracket_2__2.stl"/>
      </geometry>
      <material name="bracket_2_2_material">
        <color rgba="0.980392 0.713725 0.00392157 1"/>
      </material>
    </visual>
    <collision>
      <origin xyz="0 -0.06435 -0.003" rpy="-0 0 1.5708"/>
      <geometry>
        <mesh filename="package://assets/bracket_2__2.stl"/>
      </geometry>
    </collision>
    <!-- Part bracket_1 -->
    <visual>
      <origin xyz="0 -0.06435 -0.003" rpy="-0 0 1.5708"/>
      <geometry>
        <mesh filename="package://assets/bracket_1.stl"/>
      </geometry>
      <material name="bracket_1_material">
        <color rgba="0.980392 0.713725 0.00392157 1"/>
      </material>
    </visual>
    <collision>
      <origin xyz="0 -0.06435 -0.003" rpy="-0 0 1.5708"/>
      <geometry>
        <mesh filename="package://assets/bracket_1.stl"/>
      </geometry>
    </collision>
    <!-- Part bracket_1_2 -->
    <visual>
      <origin xyz="0 -0.06435 -0.003" rpy="-0 0 1.5708"/>
      <geometry>
        <mesh filename="package://assets/bracket_1__2.stl"/>
      </geometry>
      <material name="bracket_1_2_material">
        <color rgba="0.980392 0.713725 0.00392157 1"/>
      </material>
    </visual>
    <collision>
      <origin xyz="0 -0.06435 -0.003" rpy="-0 0 1.5708"/>
      <geometry>
        <mesh filename="package://assets/bracket_1__2.stl"/>
      </geometry>
    </collision>
  </link>
  <!-- Link urdf_link3 -->
  <link name="urdf_link3">
    <inertial>
      <origin xyz="0.0805495 4.38224e-06 -0.0360495" rpy="0 0 0"/>
      <mass value="0.496857"/>
      <inertia ixx="0.000386785" ixy="1.065e-08" ixz="0.000140755" iyy="0.0025875" iyz="-5.043e-09" izz="0.00240514"/>
    </inertial>
    <!-- Part link_3_1_waterjet -->
    <visual>
      <origin xyz="0.0805 -0.0215 -0.03605" rpy="-1.5708 1.5708 0"/>
      <geometry>
        <mesh filename="package://assets/link_3_1_waterjet.stl"/>
      </geometry>
      <material name="link_3_1_waterjet_material">
        <color rgba="0.231373 0.380392 0.705882 1"/>
      </material>
    </visual>
    <collision>
      <origin xyz="0.0805 -0.0215 -0.03605" rpy="-1.5708 1.5708 0"/>
      <geometry>
        <mesh filename="package://assets/link_3_1_waterjet.stl"/>
      </geometry>
    </collision>
    <!-- Part link_3_2__waterjet -->
    <visual>
      <origin xyz="0.08175 -0.0215 -0.03605" rpy="-1.5708 1.5708 0"/>
      <geometry>
        <mesh filename="package://assets/link_3_2__waterjet.stl"/>
      </geometry>
      <material name="link_3_2__waterjet_material">
        <color rgba="0.231373 0.380392 0.705882 1"/>
      </material>
    </visual>
    <collision>
      <origin xyz="0.08175 -0.0215 -0.03605" rpy="-1.5708 1.5708 0"/>
      <geometry>
        <mesh filename="package://assets/link_3_2__waterjet.stl"/>
      </geometry>
    </collision>
    <!-- Part casing_4 -->
    <visual>
      <origin xyz="0.1435 -0 -0.0498" rpy="1.5708 -0 0"/>
      <geometry>
        <mesh filename="package://assets/casing.stl"/>
      </geometry>
      <material name="casing_4_material">
        <color rgba="0.14902 0.129412 0.129412 1"/>
      </material>
    </visual>
    <collision>
      <origin xyz="0.1435 -0 -0.0498" rpy="1.5708 -0 0"/>
      <geometry>
        <mesh filename="package://assets/casing.stl"/>
      </geometry>
    </collision>
    <!-- Part wj_fdp0_0005_danpan_20181204_4_2 -->
    <visual>
      <origin xyz="0.161 -0 -0.0013" rpy="1.5708 0 -3.14159"/>
      <geometry>
        <mesh filename="package://assets/wj_fdp0_0005_danpan_20181204_4.stl"/>
      </geometry>
      <material name="wj_fdp0_0005_danpan_20181204_4_2_material">
        <color rgba="0.647059 0.647059 0.647059 1"/>
      </material>
    </visual>
    <collision>
      <origin xyz="0.161 -0 -0.0013" rpy="1.5708 0 -3.14159"/>
      <geometry>
        <mesh filename="package://assets/wj_fdp0_0005_danpan_20181204_4.stl"/>
      </geometry>
    </collision>
    <!-- Part output_disk_free_spining_2 -->
    <visual>
      <origin xyz="0.161 -0 -0.0764" rpy="1.5708 0 -3.14159"/>
      <geometry>
        <mesh filename="package://assets/output_disk_free_spining.stl"/>
      </geometry>
      <material name="output_disk_free_spining_2_material">
        <color rgba="0.647059 0.647059 0.647059 1"/>
      </material>
    </visual>
    <collision>
      <origin xyz="0.161 -0 -0.0764" rpy="1.5708 0 -3.14159"/>
      <geometry>
        <mesh filename="package://assets/output_disk_free_spining.stl"/>
      </geometry>
    </collision>
    <!-- Part outputgear_41_2 -->
    <visual>
      <origin xyz="0.161 -0 -0.0393" rpy="-0 -0 -0"/>
      <geometry>
        <mesh filename="package://assets/outputgear_41.stl"/>
      </geometry>
      <material name="outputgear_41_2_material">
        <color rgba="0.14902 0.129412 0.129412 1"/>
      </material>
    </visual>
    <collision>
      <origin xyz="0.161 -0 -0.0393" rpy="-0 -0 -0"/>
      <geometry>
        <mesh filename="package://assets/outputgear_41.stl"/>
      </geometry>
    </collision>
    <!-- Part casing_5 -->
    <visual>
      <origin xyz="0.1435 -0 -0.0053" rpy="-1.5708 0 -3.14159"/>
      <geometry>
        <mesh filename="package://assets/casing__2.stl"/>
      </geometry>
      <material name="casing_5_material">
        <color rgba="0.14902 0.129412 0.129412 1"/>
      </material>
    </visual>
    <collision>
      <origin xyz="0.1435 -0 -0.0053" rpy="-1.5708 0 -3.14159"/>
      <geometry>
        <mesh filename="package://assets/casing__2.stl"/>
      </geometry>
    </collision>
    <!-- Part casing_6 -->
    <visual>
      <origin xyz="0.1435 -0 -0.0668" rpy="1.5708 0 -3.14159"/>
      <geometry>
        <mesh filename="package://assets/casing__3.stl"/>
      </geometry>
      <material name="casing_6_material">
        <color rgba="0.14902 0.129412 0.129412 1"/>
      </material>
    </visual>
    <collision>
      <origin xyz="0.1435 -0 -0.0668" rpy="1.5708 0 -3.14159"/>
      <geometry>
        <mesh filename="package://assets/casing__3.stl"/>
      </geometry>
    </collision>
    <!-- Part wj_dp00_0011_17_2 -->
    <visual>
      <origin xyz="0.161 -0 -0.0005" rpy="-1.5708 0 0"/>
      <geometry>
        <mesh filename="package://assets/wj_dp00_0011_17.stl"/>
      </geometry>
      <material name="wj_dp00_0011_17_2_material">
        <color rgba="0.647059 0.647059 0.647059 1"/>
      </material>
    </visual>
    <collision>
      <origin xyz="0.161 -0 -0.0005" rpy="-1.5708 0 0"/>
      <geometry>
        <mesh filename="package://assets/wj_dp00_0011_17.stl"/>
      </geometry>
    </collision>
    <!-- Part output_shaft_2 -->
    <visual>
      <origin xyz="0.161 -0 -0.0711" rpy="1.5708 0 -3.14159"/>
      <geometry>
        <mesh filename="package://assets/output_shaft.stl"/>
      </geometry>
      <material name="output_shaft_2_material">
        <color rgba="0.647059 0.647059 0.647059 1"/>
      </material>
    </visual>
    <collision>
      <origin xyz="0.161 -0 -0.0711" rpy="1.5708 0 -3.14159"/>
      <geometry>
        <mesh filename="package://assets/output_shaft.stl"/>
      </geometry>
    </collision>
    <!-- Part casing_7 -->
    <visual>
      <origin xyz="0.0175 -0 -0.0223" rpy="-1.5708 0 -3.14159"/>
      <geometry>
        <mesh filename="package://assets/casing.stl"/>
      </geometry>
      <material name="casing_7_material">
        <color rgba="0.14902 0.129412 0.129412 1"/>
      </material>
    </visual>
    <collision>
      <origin xyz="0.0175 -0 -0.0223" rpy="-1.5708 0 -3.14159"/>
      <geometry>
        <mesh filename="package://assets/casing.stl"/>
      </geometry>
    </collision>
    <!-- Part wj_fdp0_0005_danpan_20181204_4_3 -->
    <visual>
      <origin xyz="0 0 -0.0708" rpy="-1.5708 0 0"/>
      <geometry>
        <mesh filename="package://assets/wj_fdp0_0005_danpan_20181204_4.stl"/>
      </geometry>
      <material name="wj_fdp0_0005_danpan_20181204_4_3_material">
        <color rgba="0.647059 0.647059 0.647059 1"/>
      </material>
    </visual>
    <collision>
      <origin xyz="0 0 -0.0708" rpy="-1.5708 0 0"/>
      <geometry>
        <mesh filename="package://assets/wj_fdp0_0005_danpan_20181204_4.stl"/>
      </geometry>
    </collision>
    <!-- Part output_disk_free_spining_3 -->
    <visual>
      <origin xyz="-0 -0 0.0043" rpy="-1.5708 0 0"/>
      <geometry>
        <mesh filename="package://assets/output_disk_free_spining.stl"/>
      </geometry>
      <material name="output_disk_free_spining_3_material">
        <color rgba="0.647059 0.647059 0.647059 1"/>
      </material>
    </visual>
    <collision>
      <origin xyz="-0 -0 0.0043" rpy="-1.5708 0 0"/>
      <geometry>
        <mesh filename="package://assets/output_disk_free_spining.stl"/>
      </geometry>
    </collision>
    <!-- Part outputgear_41_3 -->
    <visual>
      <origin xyz="0 0 -0.0328" rpy="3.14159 0 -3.14159"/>
      <geometry>
        <mesh filename="package://assets/outputgear_41.stl"/>
      </geometry>
      <material name="outputgear_41_3_material">
        <color rgba="0.14902 0.129412 0.129412 1"/>
      </material>
    </visual>
    <collision>
      <origin xyz="0 0 -0.0328" rpy="3.14159 0 -3.14159"/>
      <geometry>
        <mesh filename="package://assets/outputgear_41.stl"/>
      </geometry>
    </collision>
    <!-- Part casing_8 -->
    <visual>
      <origin xyz="0.0175 0 -0.0668" rpy="1.5708 -0 -0"/>
      <geometry>
        <mesh filename="package://assets/casing__2.stl"/>
      </geometry>
      <material name="casing_8_material">
        <color rgba="0.14902 0.129412 0.129412 1"/>
      </material>
    </visual>
    <collision>
      <origin xyz="0.0175 0 -0.0668" rpy="1.5708 -0 -0"/>
      <geometry>
        <mesh filename="package://assets/casing__2.stl"/>
      </geometry>
    </collision>
    <!-- Part casing_9 -->
    <visual>
      <origin xyz="0.0175 -0 -0.0053" rpy="-1.5708 0 0"/>
      <geometry>
        <mesh filename="package://assets/casing__3.stl"/>
      </geometry>
      <material name="casing_9_material">
        <color rgba="0.14902 0.129412 0.129412 1"/>
      </material>
    </visual>
    <collision>
      <origin xyz="0.0175 -0 -0.0053" rpy="-1.5708 0 0"/>
      <geometry>
        <mesh filename="package://assets/casing__3.stl"/>
      </geometry>
    </collision>
    <!-- Part wj_dp00_0011_17_3 -->
    <visual>
      <origin xyz="0 0 -0.0716" rpy="1.5708 0 -3.14159"/>
      <geometry>
        <mesh filename="package://assets/wj_dp00_0011_17.stl"/>
      </geometry>
      <material name="wj_dp00_0011_17_3_material">
        <color rgba="0.647059 0.647059 0.647059 1"/>
      </material>
    </visual>
    <collision>
      <origin xyz="0 0 -0.0716" rpy="1.5708 0 -3.14159"/>
      <geometry>
        <mesh filename="package://assets/wj_dp00_0011_17.stl"/>
      </geometry>
    </collision>
    <!-- Part output_shaft_3 -->
    <visual>
      <origin xyz="0 0 -0.001" rpy="-1.5708 0 0"/>
      <geometry>
        <mesh filename="package://assets/output_shaft.stl"/>
      </geometry>
      <material name="output_shaft_3_material">
        <color rgba="0.647059 0.647059 0.647059 1"/>
      </material>
    </visual>
    <collision>
      <origin xyz="0 0 -0.001" rpy="-1.5708 0 0"/>
      <geometry>
        <mesh filename="package://assets/output_shaft.stl"/>
      </geometry>
    </collision>
  </link>
  <!-- Link urdf_link4 -->
  <link name="urdf_link4">
    <inertial>
      <origin xyz="-0 0.0647118 0.03635" rpy="0 0 0"/>
      <mass value="0.103498"/>
      <inertia ixx="0.000154243" ixy="-0" ixz="-0" iyy="0.000127312" iyz="-0" izz="0.000155274"/>
    </inertial>
    <!-- Part bracket_2_3 -->
    <visual>
      <origin xyz="-0 0.06435 0.0757" rpy="-3.14159 0 -1.5708"/>
      <geometry>
        <mesh filename="package://assets/bracket_2.stl"/>
      </geometry>
      <material name="bracket_2_3_material">
        <color rgba="0.980392 0.713725 0.00392157 1"/>
      </material>
    </visual>
    <collision>
      <origin xyz="-0 0.06435 0.0757" rpy="-3.14159 0 -1.5708"/>
      <geometry>
        <mesh filename="package://assets/bracket_2.stl"/>
      </geometry>
    </collision>
    <!-- Part bracket_2_4 -->
    <visual>
      <origin xyz="-0 0.06435 0.0757" rpy="-3.14159 0 -1.5708"/>
      <geometry>
        <mesh filename="package://assets/bracket_2__2.stl"/>
      </geometry>
      <material name="bracket_2_4_material">
        <color rgba="0.980392 0.713725 0.00392157 1"/>
      </material>
    </visual>
    <collision>
      <origin xyz="-0 0.06435 0.0757" rpy="-3.14159 0 -1.5708"/>
      <geometry>
        <mesh filename="package://assets/bracket_2__2.stl"/>
      </geometry>
    </collision>
    <!-- Part bracket_1_3 -->
    <visual>
      <origin xyz="-0 0.06435 0.0757" rpy="-3.14159 0 -1.5708"/>
      <geometry>
        <mesh filename="package://assets/bracket_1.stl"/>
      </geometry>
      <material name="bracket_1_3_material">
        <color rgba="0.980392 0.713725 0.00392157 1"/>
      </material>
    </visual>
    <collision>
      <origin xyz="-0 0.06435 0.0757" rpy="-3.14159 0 -1.5708"/>
      <geometry>
        <mesh filename="package://assets/bracket_1.stl"/>
      </geometry>
    </collision>
    <!-- Part bracket_1_4 -->
    <visual>
      <origin xyz="-0 0.06435 0.0757" rpy="-3.14159 0 -1.5708"/>
      <geometry>
        <mesh filename="package://assets/bracket_1__2.stl"/>
      </geometry>
      <material name="bracket_1_4_material">
        <color rgba="0.980392 0.713725 0.00392157 1"/>
      </material>
    </visual>
    <collision>
      <origin xyz="-0 0.06435 0.0757" rpy="-3.14159 0 -1.5708"/>
      <geometry>
        <mesh filename="package://assets/bracket_1__2.stl"/>
      </geometry>
    </collision>
  </link>
  <!-- Link urdf_link5 -->
  <link name="urdf_link5">
    <inertial>
      <origin xyz="-0.0459733 -0.0285789 -0.0333796" rpy="0 0 0"/>
      <mass value="0.403309"/>
      <inertia ixx="0.000483596" ixy="-0.000261342" ixz="-4.94564e-05" iyy="0.00210963" iyz="-1.40932e-05" izz="0.00223346"/>
    </inertial>
    <!-- Part link_1_4_bracket_2 -->
    <visual>
      <origin xyz="-0.08275 -0.06885 -0.03605" rpy="1.5708 -0 3.14159"/>
      <geometry>
        <mesh filename="package://assets/link_1_4_bracket.stl"/>
      </geometry>
      <material name="link_1_4_bracket_2_material">
        <color rgba="0.372549 0.654902 0.239216 1"/>
      </material>
    </visual>
    <collision>
      <origin xyz="-0.08275 -0.06885 -0.03605" rpy="1.5708 -0 3.14159"/>
      <geometry>
        <mesh filename="package://assets/link_1_4_bracket.stl"/>
      </geometry>
    </collision>
    <!-- Part link_1_3_waterjet_2 -->
    <visual>
      <origin xyz="-0.08275 -0.06885 -0.03605" rpy="1.5708 -0 3.14159"/>
      <geometry>
        <mesh filename="package://assets/link_1_3_waterjet.stl"/>
      </geometry>
      <material name="link_1_3_waterjet_2_material">
        <color rgba="0.372549 0.654902 0.239216 1"/>
      </material>
    </visual>
    <collision>
      <origin xyz="-0.08275 -0.06885 -0.03605" rpy="1.5708 -0 3.14159"/>
      <geometry>
        <mesh filename="package://assets/link_1_3_waterjet.stl"/>
      </geometry>
    </collision>
    <!-- Part link_2_2_cnc_mill_2 -->
    <visual>
      <origin xyz="-0.08275 -0.06885 -0.03605" rpy="1.5708 -0 3.14159"/>
      <geometry>
        <mesh filename="package://assets/link_2_2_cnc_mill.stl"/>
      </geometry>
      <material name="link_2_2_cnc_mill_2_material">
        <color rgba="0.372549 0.654902 0.239216 1"/>
      </material>
    </visual>
    <collision>
      <origin xyz="-0.08275 -0.06885 -0.03605" rpy="1.5708 -0 3.14159"/>
      <geometry>
        <mesh filename="package://assets/link_2_2_cnc_mill.stl"/>
      </geometry>
    </collision>
    <!-- Part link_1_1_bracket_2 -->
    <visual>
      <origin xyz="-0.08275 -0.06885 -0.03605" rpy="1.5708 -0 3.14159"/>
      <geometry>
        <mesh filename="package://assets/link_1_1_bracket.stl"/>
      </geometry>
      <material name="link_1_1_bracket_2_material">
        <color rgba="0.372549 0.654902 0.239216 1"/>
      </material>
    </visual>
    <collision>
      <origin xyz="-0.08275 -0.06885 -0.03605" rpy="1.5708 -0 3.14159"/>
      <geometry>
        <mesh filename="package://assets/link_1_1_bracket.stl"/>
      </geometry>
    </collision>
    <!-- Part casing_10 -->
    <visual>
      <origin xyz="-0 -0.0175 -0.0223" rpy="-1.5708 -0 1.5708"/>
      <geometry>
        <mesh filename="package://assets/casing.stl"/>
      </geometry>
      <material name="casing_10_material">
        <color rgba="0.14902 0.129412 0.129412 1"/>
      </material>
    </visual>
    <collision>
      <origin xyz="-0 -0.0175 -0.0223" rpy="-1.5708 -0 1.5708"/>
      <geometry>
        <mesh filename="package://assets/casing.stl"/>
      </geometry>
    </collision>
    <!-- Part wj_fdp0_0005_danpan_20181204_4_4 -->
    <visual>
      <origin xyz="-0 -0 -0.0708" rpy="-1.5708 -0 -1.5708"/>
      <geometry>
        <mesh filename="package://assets/wj_fdp0_0005_danpan_20181204_4.stl"/>
      </geometry>
      <material name="wj_fdp0_0005_danpan_20181204_4_4_material">
        <color rgba="0.647059 0.647059 0.647059 1"/>
      </material>
    </visual>
    <collision>
      <origin xyz="-0 -0 -0.0708" rpy="-1.5708 -0 -1.5708"/>
      <geometry>
        <mesh filename="package://assets/wj_fdp0_0005_danpan_20181204_4.stl"/>
      </geometry>
    </collision>
    <!-- Part output_disk_free_spining_4 -->
    <visual>
      <origin xyz="0 0 0.0043" rpy="-1.5708 -0 -1.5708"/>
      <geometry>
        <mesh filename="package://assets/output_disk_free_spining.stl"/>
      </geometry>
      <material name="output_disk_free_spining_4_material">
        <color rgba="0.647059 0.647059 0.647059 1"/>
      </material>
    </visual>
    <collision>
      <origin xyz="0 0 0.0043" rpy="-1.5708 -0 -1.5708"/>
      <geometry>
        <mesh filename="package://assets/output_disk_free_spining.stl"/>
      </geometry>
    </collision>
    <!-- Part outputgear_41_4 -->
    <visual>
      <origin xyz="-0 -0 -0.0328" rpy="-3.14159 0 1.5708"/>
      <geometry>
        <mesh filename="package://assets/outputgear_41.stl"/>
      </geometry>
      <material name="outputgear_41_4_material">
        <color rgba="0.14902 0.129412 0.129412 1"/>
      </material>
    </visual>
    <collision>
      <origin xyz="-0 -0 -0.0328" rpy="-3.14159 0 1.5708"/>
      <geometry>
        <mesh filename="package://assets/outputgear_41.stl"/>
      </geometry>
    </collision>
    <!-- Part casing_11 -->
    <visual>
      <origin xyz="-0 -0.0175 -0.0668" rpy="1.5708 0 -1.5708"/>
      <geometry>
        <mesh filename="package://assets/casing__2.stl"/>
      </geometry>
      <material name="casing_11_material">
        <color rgba="0.14902 0.129412 0.129412 1"/>
      </material>
    </visual>
    <collision>
      <origin xyz="-0 -0.0175 -0.0668" rpy="1.5708 0 -1.5708"/>
      <geometry>
        <mesh filename="package://assets/casing__2.stl"/>
      </geometry>
    </collision>
    <!-- Part casing_12 -->
    <visual>
      <origin xyz="-0 -0.0175 -0.0053" rpy="-1.5708 -0 -1.5708"/>
      <geometry>
        <mesh filename="package://assets/casing__3.stl"/>
      </geometry>
      <material name="casing_12_material">
        <color rgba="0.14902 0.129412 0.129412 1"/>
      </material>
    </visual>
    <collision>
      <origin xyz="-0 -0.0175 -0.0053" rpy="-1.5708 -0 -1.5708"/>
      <geometry>
        <mesh filename="package://assets/casing__3.stl"/>
      </geometry>
    </collision>
    <!-- Part wj_dp00_0011_17_4 -->
    <visual>
      <origin xyz="-0 -0 -0.0716" rpy="1.5708 1e-12 1.5708"/>
      <geometry>
        <mesh filename="package://assets/wj_dp00_0011_17.stl"/>
      </geometry>
      <material name="wj_dp00_0011_17_4_material">
        <color rgba="0.647059 0.647059 0.647059 1"/>
      </material>
    </visual>
    <collision>
      <origin xyz="-0 -0 -0.0716" rpy="1.5708 1e-12 1.5708"/>
      <geometry>
        <mesh filename="package://assets/wj_dp00_0011_17.stl"/>
      </geometry>
    </collision>
    <!-- Part output_shaft_4 -->
    <visual>
      <origin xyz="-0 -0 -0.001" rpy="-1.5708 -0 -1.5708"/>
      <geometry>
        <mesh filename="package://assets/output_shaft.stl"/>
      </geometry>
      <material name="output_shaft_4_material">
        <color rgba="0.647059 0.647059 0.647059 1"/>
      </material>
    </visual>
    <collision>
      <origin xyz="-0 -0 -0.001" rpy="-1.5708 -0 -1.5708"/>
      <geometry>
        <mesh filename="package://assets/output_shaft.stl"/>
      </geometry>
    </collision>
    <!-- Part cover_4 -->
    <visual>
      <origin xyz="-0.1508 -0.04565 -0.03605" rpy="3.14159 -0 -1.5708"/>
      <geometry>
        <mesh filename="package://assets/cover.stl"/>
      </geometry>
      <material name="cover_4_material">
        <color rgba="0.341176 0.32549 0.32549 1"/>
      </material>
    </visual>
    <collision>
      <origin xyz="-0.1508 -0.04565 -0.03605" rpy="3.14159 -0 -1.5708"/>
      <geometry>
        <mesh filename="package://assets/cover.stl"/>
      </geometry>
    </collision>
    <!-- Part ge_27_2 -->
    <visual>
      <origin xyz="-0.1508 -0.0381812 -0.0540812" rpy="-3.14159 0.785398 -1.5708"/>
      <geometry>
        <mesh filename="package://assets/ge_27.stl"/>
      </geometry>
      <material name="ge_27_2_material">
        <color rgba="1 0 0 1"/>
      </material>
    </visual>
    <collision>
      <origin xyz="-0.1508 -0.0381812 -0.0540812" rpy="-3.14159 0.785398 -1.5708"/>
      <geometry>
        <mesh filename="package://assets/ge_27.stl"/>
      </geometry>
    </collision>
    <!-- Part cover_5 -->
    <visual>
      <origin xyz="-0.1508 -0.04565 -0.03605" rpy="3.14159 -0 -1.5708"/>
      <geometry>
        <mesh filename="package://assets/cover__2.stl"/>
      </geometry>
      <material name="cover_5_material">
        <color rgba="0.341176 0.32549 0.32549 1"/>
      </material>
    </visual>
    <collision>
      <origin xyz="-0.1508 -0.04565 -0.03605" rpy="3.14159 -0 -1.5708"/>
      <geometry>
        <mesh filename="package://assets/cover__2.stl"/>
      </geometry>
    </collision>
    <!-- Part cover_6 -->
    <visual>
      <origin xyz="-0.1508 -0.04565 -0.03605" rpy="3.14159 -0 -1.5708"/>
      <geometry>
        <mesh filename="package://assets/cover__3.stl"/>
      </geometry>
      <material name="cover_6_material">
        <color rgba="0.341176 0.32549 0.32549 1"/>
      </material>
    </visual>
    <collision>
      <origin xyz="-0.1508 -0.04565 -0.03605" rpy="3.14159 -0 -1.5708"/>
      <geometry>
        <mesh filename="package://assets/cover__3.stl"/>
      </geometry>
    </collision>
    <!-- Part mounting_bracket_bottom_2 -->
    <visual>
      <origin xyz="-0.141 -0.0625 -0.03605" rpy="1.5708 -0 3.14159"/>
      <geometry>
        <mesh filename="package://assets/mounting_bracket_bottom.stl"/>
      </geometry>
      <material name="mounting_bracket_bottom_2_material">
        <color rgba="0.14902 0.121569 0.121569 1"/>
      </material>
    </visual>
    <collision>
      <origin xyz="-0.141 -0.0625 -0.03605" rpy="1.5708 -0 3.14159"/>
      <geometry>
        <mesh filename="package://assets/mounting_bracket_bottom.stl"/>
      </geometry>
    </collision>
  </link>
  <!-- Link urdf_ee -->
  <link name="urdf_ee">
    <inertial>
      <origin xyz="0.0236472 -0.000215883 -0.0369073" rpy="0 0 0"/>
      <mass value="0.222889"/>
      <inertia ixx="0.000319242" ixy="-1.13863e-06" ixz="6.69308e-05" iyy="0.000565736" iyz="-1.06227e-06" izz="0.000679483"/>
    </inertial>
    <!-- Part ee_main_body__cnc_machine_2 -->
    <visual>
      <origin xyz="0 0 -0.065875" rpy="0 -0 1.5708"/>
      <geometry>
        <mesh filename="package://assets/ee_main_body__cnc_machine.stl"/>
      </geometry>
      <material name="ee_main_body__cnc_machine_2_material">
        <color rgba="0.866667 0.321569 0.156863 1"/>
      </material>
    </visual>
    <collision>
      <origin xyz="0 0 -0.065875" rpy="0 -0 1.5708"/>
      <geometry>
        <mesh filename="package://assets/ee_main_body__cnc_machine.stl"/>
      </geometry>
    </collision>
    <!-- Part camera_mount__3d_printed -->
    <visual>
      <origin xyz="-0.00465 -0 -0.018525" rpy="-3.14159 0 1.5708"/>
      <geometry>
        <mesh filename="package://assets/camera_mount__3d_printed.stl"/>
      </geometry>
      <material name="camera_mount__3d_printed_material">
        <color rgba="0.917647 0.917647 0.917647 1"/>
      </material>
    </visual>
    <collision>
      <origin xyz="-0.00465 -0 -0.018525" rpy="-3.14159 0 1.5708"/>
      <geometry>
        <mesh filename="package://assets/camera_mount__3d_printed.stl"/>
      </geometry>
    </collision>
    <!-- Part link_0_2 -->
    <visual>
      <origin xyz="-0 -0 -0.0187" rpy="0 0 0.785398"/>
      <geometry>
        <mesh filename="package://assets/link_0.stl"/>
      </geometry>
      <material name="link_0_2_material">
        <color rgba="0.866667 0.321569 0.156863 1"/>
      </material>
    </visual>
    <collision>
      <origin xyz="-0 -0 -0.0187" rpy="0 0 0.785398"/>
      <geometry>
        <mesh filename="package://assets/link_0.stl"/>
      </geometry>
    </collision>
    <!-- Part servo_horn_2 -->
    <visual>
      <origin xyz="0.0180312 0.0180312 0.0081" rpy="-1.5708 -0 0.785398"/>
      <geometry>
        <mesh filename="package://assets/servo_horn.stl"/>
      </geometry>
      <material name="servo_horn_2_material">
        <color rgba="0.960784 0.960784 0.964706 1"/>
      </material>
    </visual>
    <collision>
      <origin xyz="0.0180312 0.0180312 0.0081" rpy="-1.5708 -0 0.785398"/>
      <geometry>
        <mesh filename="package://assets/servo_horn.stl"/>
      </geometry>
    </collision>
    <!-- Part 93655a224_no_threads_male_female_threaded_hex_standoff_5 -->
    <visual>
      <origin xyz="-0.023 -0.013 -0.0627" rpy="0 -0 -1.5708"/>
      <geometry>
        <mesh filename="package://assets/93655a224_no_threads_male_female_threaded_hex_standoff.stl"/>
      </geometry>
      <material name="93655a224_no_threads_male_female_threaded_hex_standoff_5_material">
        <color rgba="0.866667 0.321569 0.156863 1"/>
      </material>
    </visual>
    <collision>
      <origin xyz="-0.023 -0.013 -0.0627" rpy="0 -0 -1.5708"/>
      <geometry>
        <mesh filename="package://assets/93655a224_no_threads_male_female_threaded_hex_standoff.stl"/>
      </geometry>
    </collision>
    <!-- Part pin_support_plate__waterjetted_2 -->
    <visual>
      <origin xyz="-0 -0 -0.022525" rpy="-3.14159 0 -1.5708"/>
      <geometry>
        <mesh filename="package://assets/pin_support_plate__waterjetted.stl"/>
      </geometry>
      <material name="pin_support_plate__waterjetted_2_material">
        <color rgba="0.866667 0.321569 0.156863 1"/>
      </material>
    </visual>
    <collision>
      <origin xyz="-0 -0 -0.022525" rpy="-3.14159 0 -1.5708"/>
      <geometry>
        <mesh filename="package://assets/pin_support_plate__waterjetted.stl"/>
      </geometry>
    </collision>
    <!-- Part 93657a001_nylon_unthreaded_spacer_5 -->
    <visual>
      <origin xyz="-0.023 0.013 -0.0267" rpy="-3.14159 0 -1.5708"/>
      <geometry>
        <mesh filename="package://assets/93657a001_nylon_unthreaded_spacer.stl"/>
      </geometry>
      <material name="93657a001_nylon_unthreaded_spacer_5_material">
        <color rgba="0.866667 0.321569 0.156863 1"/>
      </material>
    </visual>
    <collision>
      <origin xyz="-0.023 0.013 -0.0267" rpy="-3.14159 0 -1.5708"/>
      <geometry>
        <mesh filename="package://assets/93657a001_nylon_unthreaded_spacer.stl"/>
      </geometry>
    </collision>
    <!-- Part 93657a001_nylon_unthreaded_spacer_6 -->
    <visual>
      <origin xyz="-0.023 -0.013 -0.0267" rpy="-3.14159 0 -1.5708"/>
      <geometry>
        <mesh filename="package://assets/93657a001_nylon_unthreaded_spacer.stl"/>
      </geometry>
      <material name="93657a001_nylon_unthreaded_spacer_6_material">
        <color rgba="0.866667 0.321569 0.156863 1"/>
      </material>
    </visual>
    <collision>
      <origin xyz="-0.023 -0.013 -0.0267" rpy="-3.14159 0 -1.5708"/>
      <geometry>
        <mesh filename="package://assets/93657a001_nylon_unthreaded_spacer.stl"/>
      </geometry>
    </collision>
    <!-- Part 93657a001_nylon_unthreaded_spacer_7 -->
    <visual>
      <origin xyz="0.023 -0.013 -0.0267" rpy="-3.14159 0 -1.5708"/>
      <geometry>
        <mesh filename="package://assets/93657a001_nylon_unthreaded_spacer.stl"/>
      </geometry>
      <material name="93657a001_nylon_unthreaded_spacer_7_material">
        <color rgba="0.866667 0.321569 0.156863 1"/>
      </material>
    </visual>
    <collision>
      <origin xyz="0.023 -0.013 -0.0267" rpy="-3.14159 0 -1.5708"/>
      <geometry>
        <mesh filename="package://assets/93657a001_nylon_unthreaded_spacer.stl"/>
      </geometry>
    </collision>
    <!-- Part 93657a001_nylon_unthreaded_spacer_8 -->
    <visual>
      <origin xyz="0.023 0.013 -0.0267" rpy="-3.14159 0 -1.5708"/>
      <geometry>
        <mesh filename="package://assets/93657a001_nylon_unthreaded_spacer.stl"/>
      </geometry>
      <material name="93657a001_nylon_unthreaded_spacer_8_material">
        <color rgba="0.866667 0.321569 0.156863 1"/>
      </material>
    </visual>
    <collision>
      <origin xyz="0.023 0.013 -0.0267" rpy="-3.14159 0 -1.5708"/>
      <geometry>
        <mesh filename="package://assets/93657a001_nylon_unthreaded_spacer.stl"/>
      </geometry>
    </collision>
    <!-- Part 93655a224_no_threads_male_female_threaded_hex_standoff_6 -->
    <visual>
      <origin xyz="-0.023 0.013 -0.0627" rpy="0 -0 -1.5708"/>
      <geometry>
        <mesh filename="package://assets/93655a224_no_threads_male_female_threaded_hex_standoff.stl"/>
      </geometry>
      <material name="93655a224_no_threads_male_female_threaded_hex_standoff_6_material">
        <color rgba="0.866667 0.321569 0.156863 1"/>
      </material>
    </visual>
    <collision>
      <origin xyz="-0.023 0.013 -0.0627" rpy="0 -0 -1.5708"/>
      <geometry>
        <mesh filename="package://assets/93655a224_no_threads_male_female_threaded_hex_standoff.stl"/>
      </geometry>
    </collision>
    <!-- Part 93655a224_no_threads_male_female_threaded_hex_standoff_7 -->
    <visual>
      <origin xyz="0.023 0.013 -0.0627" rpy="0 -0 -1.5708"/>
      <geometry>
        <mesh filename="package://assets/93655a224_no_threads_male_female_threaded_hex_standoff.stl"/>
      </geometry>
      <material name="93655a224_no_threads_male_female_threaded_hex_standoff_7_material">
        <color rgba="0.866667 0.321569 0.156863 1"/>
      </material>
    </visual>
    <collision>
      <origin xyz="0.023 0.013 -0.0627" rpy="0 -0 -1.5708"/>
      <geometry>
        <mesh filename="package://assets/93655a224_no_threads_male_female_threaded_hex_standoff.stl"/>
      </geometry>
    </collision>
    <!-- Part 93655a224_no_threads_male_female_threaded_hex_standoff_8 -->
    <visual>
      <origin xyz="0.023 -0.013 -0.0627" rpy="0 -0 -1.5708"/>
      <geometry>
        <mesh filename="package://assets/93655a224_no_threads_male_female_threaded_hex_standoff.stl"/>
      </geometry>
      <material name="93655a224_no_threads_male_female_threaded_hex_standoff_8_material">
        <color rgba="0.866667 0.321569 0.156863 1"/>
      </material>
    </visual>
    <collision>
      <origin xyz="0.023 -0.013 -0.0627" rpy="0 -0 -1.5708"/>
      <geometry>
        <mesh filename="package://assets/93655a224_no_threads_male_female_threaded_hex_standoff.stl"/>
      </geometry>
    </collision>
  </link>
  <!-- Joint from urdf_link5 to urdf_ee -->
  <joint name="5" type="revolute">
    <origin xyz="-0.1589 -0.02015 -0.03605" rpy="0 1.5708 0"/>
    <parent link="urdf_link5"/>
    <child link="urdf_ee"/>
    <axis xyz="0 0 1"/>
    <limit effort="10" velocity="10" lower="-2.96706" upper="2.96706"/>
  </joint>
  <!-- Joint from urdf_link4 to urdf_link5 -->
  <joint name="4" type="revolute">
    <origin xyz="-0.03635 0.12935 0.03635" rpy="-3.14159 1.5708 0"/>
    <parent link="urdf_link4"/>
    <child link="urdf_link5"/>
    <axis xyz="0 0 1"/>
    <limit effort="10" velocity="10" lower="-1.0472" upper="1.0472"/>
  </joint>
  <!-- Joint from urdf_link3 to urdf_link4 -->
  <joint name="3" type="revolute">
    <origin xyz="0.161 -0 0.0005" rpy="3.14159 0 0"/>
    <parent link="urdf_link3"/>
    <child link="urdf_link4"/>
    <axis xyz="0 0 1"/>
    <limit effort="10" velocity="10" lower="-3.31613" upper="0.174533"/>
  </joint>
  <!-- Joint from urdf_link2 to urdf_link3 -->
  <joint name="2" type="revolute">
    <origin xyz="0.03635 -0.12935 0.03635" rpy="-3.14159 -1.5708 0"/>
    <parent link="urdf_link2"/>
    <child link="urdf_link3"/>
    <axis xyz="0 0 1"/>
    <limit effort="10" velocity="10" lower="-0.174533" upper="3.31613"/>
  </joint>
  <!-- Joint from urdf_link1 to urdf_link2 -->
  <joint name="1" type="revolute">
    <origin xyz="-0.03605 0.02015 0.1589" rpy="3.14159 -1.5708 0"/>
    <parent link="urdf_link1"/>
    <child link="urdf_link2"/>
    <axis xyz="0 0 1"/>
    <limit effort="10" velocity="10" lower="-1.0472" upper="1.0472"/>
  </joint>
  <!-- Joint from urdf_base to urdf_link1 -->
  <joint name="0" type="revolute">
    <origin xyz="0 0 0.00485" rpy="-0 0 -0"/>
    <parent link="urdf_base"/>
    <child link="urdf_link1"/>
    <axis xyz="0 0 1"/>
    <limit effort="10" velocity="10" lower="-2.96706" upper="2.96706"/>
  </joint>
</robot>
